<?xml version="1.0"?>
<robot xmlns:xacro="http://www.ros.org/wiki/xacro" name="transport_robot">

  <!-- Arguments -->
  <xacro:arg name="robot_name" default="robot"/>

  <!-- Properties -->
  <xacro:property name="base_width" value="0.6"/>
  <xacro:property name="base_length" value="0.8"/>
  <xacro:property name="base_height" value="0.2"/>
  <xacro:property name="wheel_radius" value="0.1"/>
  <xacro:property name="wheel_width" value="0.05"/>
  <xacro:property name="wheel_offset_x" value="0.3"/>
  <xacro:property name="wheel_offset_y" value="0.35"/>
  <xacro:property name="wheel_offset_z" value="-0.05"/>

  <!-- Base link -->
  <link name="base_link">
    <visual>
      <origin xyz="0 0 0" rpy="0 0 0"/>
      <geometry>
        <box size="${base_length} ${base_width} ${base_height}"/>
      </geometry>
      <material name="blue">
        <color rgba="0.2 0.2 0.8 1.0"/>
      </material>
    </visual>
    <collision>
      <origin xyz="0 0 0" rpy="0 0 0"/>
      <geometry>
        <box size="${base_length} ${base_width} ${base_height}"/>
      </geometry>
    </collision>
    <inertial>
      <origin xyz="-0.3 0 0" rpy="0 0 0"/>
      <mass value="20.0"/>
      <!-- 正確な慣性テンソルを計算 -->
      <inertia 
        ixx="${(1.0/12.0) * 20.0 * (base_width*base_width + base_height*base_height)}" 
        ixy="0.0" 
        ixz="0.0" 
        iyy="${(1.0/12.0) * 20.0 * (base_length*base_length + base_height*base_height)}" 
        iyz="0.0" 
        izz="${(1.0/12.0) * 20.0 * (base_length*base_length + base_width*base_width)}"/>
    </inertial>
  </link>

  <!-- Wheel macro -->
  <xacro:macro name="wheel" params="prefix x y">
    <link name="${prefix}_wheel">
      <visual>
        <origin xyz="0 0 0" rpy="1.5708 0 0"/>
        <geometry>
          <cylinder radius="${wheel_radius}" length="${wheel_width}"/>
        </geometry>
        <material name="black">
          <color rgba="0.1 0.1 0.1 1.0"/>
        </material>
      </visual>
      <collision>
        <origin xyz="0 0 0" rpy="1.5708 0 0"/>
        <geometry>
          <cylinder radius="${wheel_radius}" length="${wheel_width}"/>
        </geometry>
      </collision>
      <inertial>
        <origin xyz="0 0 0" rpy="1.5708 0 0"/>
        <mass value="2.0"/>
        <!-- 円柱の慣性テンソル -->
        <inertia 
          ixx="${(1.0/12.0) * 2.0 * (3*wheel_radius*wheel_radius + wheel_width*wheel_width)}" 
          ixy="0.0" 
          ixz="0.0" 
          iyy="${(1.0/12.0) * 2.0 * (3*wheel_radius*wheel_radius + wheel_width*wheel_width)}" 
          iyz="0.0" 
          izz="${0.5 * 2.0 * wheel_radius*wheel_radius}"/>
      </inertial>
    </link>

    <joint name="${prefix}_wheel_joint" type="continuous">
      <parent link="base_link"/>
      <child link="${prefix}_wheel"/>
      <origin xyz="${x} ${y} ${wheel_offset_z}" rpy="0 0 0"/>
      <axis xyz="0 1 0"/>
    </joint>
  </xacro:macro>

  <!-- Create 4 wheels -->
  <xacro:wheel prefix="front_left" x="${wheel_offset_x}" y="${wheel_offset_y}"/>
  <xacro:wheel prefix="front_right" x="${wheel_offset_x}" y="${-wheel_offset_y}"/>
  <xacro:wheel prefix="rear_left" x="${-wheel_offset_x}" y="${wheel_offset_y}"/>
  <xacro:wheel prefix="rear_right" x="${-wheel_offset_x}" y="${-wheel_offset_y}"/>

  <!-- LiDAR sensor -->
  <link name="lidar_link">
    <visual>
      <origin xyz="0 0 0" rpy="0 0 0"/>
      <geometry>
        <cylinder radius="0.05" length="0.04"/>
      </geometry>
      <material name="red">
        <color rgba="0.8 0.2 0.2 1.0"/>
      </material>
    </visual>
    <collision>
      <origin xyz="0 0 0" rpy="0 0 0"/>
      <geometry>
        <cylinder radius="0.05" length="0.04"/>
      </geometry>
    </collision>
    <inertial>
      <origin xyz="0 0 0" rpy="0 0 0"/>
      <mass value="0.1"/>
      <inertia ixx="0.001" ixy="0.0" ixz="0.0" iyy="0.001" iyz="0.0" izz="0.001"/>
    </inertial>
  </link>

  <joint name="lidar_joint" type="fixed">
    <parent link="base_link"/>
    <child link="lidar_link"/>
    <origin xyz="0 0 ${base_height/2 + 0.02}" rpy="0 0 0"/>
  </joint>

  <!-- Gazebo plugins -->
  <gazebo>
    <plugin name="differential_drive_controller" filename="libgazebo_ros_diff_drive.so">
      <ros>
        <namespace>$(arg robot_name)</namespace>
      </ros>
      <update_rate>30</update_rate>
      <left_joint>rear_left_wheel_joint</left_joint>
      <right_joint>rear_right_wheel_joint</right_joint>
      <wheel_separation>${base_width}</wheel_separation>
      <wheel_diameter>${2*wheel_radius}</wheel_diameter>
      <max_wheel_torque>20</max_wheel_torque>
      <max_wheel_acceleration>1.0</max_wheel_acceleration>
      <command_topic>cmd_vel</command_topic>
      <publish_odom>true</publish_odom>
      <publish_odom_tf>true</publish_odom_tf>
      <publish_wheel_tf>true</publish_wheel_tf>
      <odometry_topic>odom</odometry_topic>
      <odometry_frame>odom</odometry_frame>
      <robot_base_frame>base_link</robot_base_frame>
      <!-- 重要: 回転中心を後輪軸に設定 -->
      <wheel_separation>${base_width}</wheel_separation>
      <wheel_diameter>${2*wheel_radius}</wheel_diameter>
      <!-- オドメトリの基準点を調整 -->
      <odometry_source>world</odometry_source>
    </plugin>
  </gazebo>

  <!-- LiDAR Gazebo plugin -->
  <gazebo reference="lidar_link">
    <sensor type="ray" name="lidar_sensor">
      <pose>0 0 0 0 0 0</pose>
      <visualize>true</visualize>
      <update_rate>10</update_rate>
      <ray>
        <scan>
          <horizontal>
            <samples>360</samples>
            <resolution>1</resolution>
            <min_angle>-3.14159</min_angle>
            <max_angle>3.14159</max_angle>
          </horizontal>
        </scan>
        <range>
          <min>0.1</min>
          <max>10.0</max>
          <resolution>0.01</resolution>
        </range>
        <noise>
          <type>gaussian</type>
          <mean>0.0</mean>
          <stddev>0.01</stddev>
        </noise>
      </ray>
      <plugin name="gazebo_ros_lidar_controller" filename="libgazebo_ros_ray_sensor.so">
        <ros>
          <namespace>$(arg robot_name)</namespace>
          <remapping>~/out:=scan</remapping>
        </ros>
        <output_type>sensor_msgs/LaserScan</output_type>
        <frame_name>lidar_link</frame_name>
      </plugin>
    </sensor>
  </gazebo>

  <!-- Gazebo materials -->
  <gazebo reference="base_link">
    <material>Gazebo/Blue</material>
  </gazebo>

  <gazebo reference="front_left_wheel">
    <material>Gazebo/Black</material>
  </gazebo>

  <gazebo reference="front_right_wheel">
    <material>Gazebo/Black</material>
  </gazebo>

  <gazebo reference="rear_left_wheel">
    <material>Gazebo/Black</material>
  </gazebo>

  <gazebo reference="rear_right_wheel">
    <material>Gazebo/Black</material>
  </gazebo>

</robot>
