<?xml version="1.0" ?>
<sdf version="1.6">
  <model name="simple_transport_robot">
    <pose>0 0 0.1 0 0 0</pose>
    
    <!-- Base Link -->
    <link name="base_link">
      <pose>0 0 0 0 0 0</pose>
      <inertial>
        <mass>20.0</mass>
        <inertia>
          <ixx>1.0</ixx>
          <ixy>0.0</ixy>
          <ixz>0.0</ixz>
          <iyy>1.0</iyy>
          <iyz>0.0</iyz>
          <izz>1.0</izz>
        </inertia>
      </inertial>
      <visual name="base_visual">
        <geometry>
          <box>
            <size>0.8 0.6 0.2</size>
          </box>
        </geometry>
        <material>
          <ambient>0.2 0.2 0.8 1.0</ambient>
          <diffuse>0.2 0.2 0.8 1.0</diffuse>
        </material>
      </visual>
      <collision name="base_collision">
        <geometry>
          <box>
            <size>0.8 0.6 0.2</size>
          </box>
        </geometry>
      </collision>
    </link>

    <!-- Front Left Wheel -->
    <link name="front_left_wheel">
      <pose>0.3 0.35 -0.05 1.5708 0 0</pose>
      <inertial>
        <mass>2.0</mass>
        <inertia>
          <ixx>0.1</ixx>
          <ixy>0.0</ixy>
          <ixz>0.0</ixz>
          <iyy>0.1</iyy>
          <iyz>0.0</iyz>
          <izz>0.1</izz>
        </inertia>
      </inertial>
      <visual name="wheel_visual">
        <geometry>
          <cylinder>
            <radius>0.1</radius>
            <length>0.05</length>
          </cylinder>
        </geometry>
        <material>
          <ambient>0.1 0.1 0.1 1.0</ambient>
          <diffuse>0.1 0.1 0.1 1.0</diffuse>
        </material>
      </visual>
      <collision name="wheel_collision">
        <geometry>
          <cylinder>
            <radius>0.1</radius>
            <length>0.05</length>
          </cylinder>
        </geometry>
      </collision>
    </link>

    <!-- Front Right Wheel -->
    <link name="front_right_wheel">
      <pose>0.3 -0.35 -0.05 1.5708 0 0</pose>
      <inertial>
        <mass>2.0</mass>
        <inertia>
          <ixx>0.1</ixx>
          <ixy>0.0</ixy>
          <ixz>0.0</ixz>
          <iyy>0.1</iyy>
          <iyz>0.0</iyz>
          <izz>0.1</izz>
        </inertia>
      </inertial>
      <visual name="wheel_visual">
        <geometry>
          <cylinder>
            <radius>0.1</radius>
            <length>0.05</length>
          </cylinder>
        </geometry>
        <material>
          <ambient>0.1 0.1 0.1 1.0</ambient>
          <diffuse>0.1 0.1 0.1 1.0</diffuse>
        </material>
      </visual>
      <collision name="wheel_collision">
        <geometry>
          <cylinder>
            <radius>0.1</radius>
            <length>0.05</length>
          </cylinder>
        </geometry>
      </collision>
    </link>

    <!-- Rear Left Wheel -->
    <link name="rear_left_wheel">
      <pose>-0.3 0.35 -0.05 1.5708 0 0</pose>
      <inertial>
        <mass>2.0</mass>
        <inertia>
          <ixx>0.1</ixx>
          <ixy>0.0</ixy>
          <ixz>0.0</ixz>
          <iyy>0.1</iyy>
          <iyz>0.0</iyz>
          <izz>0.1</izz>
        </inertia>
      </inertial>
      <visual name="wheel_visual">
        <geometry>
          <cylinder>
            <radius>0.1</radius>
            <length>0.05</length>
          </cylinder>
        </geometry>
        <material>
          <ambient>0.1 0.1 0.1 1.0</ambient>
          <diffuse>0.1 0.1 0.1 1.0</diffuse>
        </material>
      </visual>
      <collision name="wheel_collision">
        <geometry>
          <cylinder>
            <radius>0.1</radius>
            <length>0.05</length>
          </cylinder>
        </geometry>
      </collision>
    </link>

    <!-- Rear Right Wheel -->
    <link name="rear_right_wheel">
      <pose>-0.3 -0.35 -0.05 1.5708 0 0</pose>
      <inertial>
        <mass>2.0</mass>
        <inertia>
          <ixx>0.1</ixx>
          <ixy>0.0</ixy>
          <ixz>0.0</ixz>
          <iyy>0.1</iyy>
          <iyz>0.0</iyz>
          <izz>0.1</izz>
        </inertia>
      </inertial>
      <visual name="wheel_visual">
        <geometry>
          <cylinder>
            <radius>0.1</radius>
            <length>0.05</length>
          </cylinder>
        </geometry>
        <material>
          <ambient>0.1 0.1 0.1 1.0</ambient>
          <diffuse>0.1 0.1 0.1 1.0</diffuse>
        </material>
      </visual>
      <collision name="wheel_collision">
        <geometry>
          <cylinder>
            <radius>0.1</radius>
            <length>0.05</length>
          </cylinder>
        </geometry>
      </collision>
    </link>

    <!-- Joints -->
    <joint name="front_left_wheel_joint" type="revolute">
      <parent>base_link</parent>
      <child>front_left_wheel</child>
      <axis>
        <xyz>0 1 0</xyz>
      </axis>
    </joint>

    <joint name="front_right_wheel_joint" type="revolute">
      <parent>base_link</parent>
      <child>front_right_wheel</child>
      <axis>
        <xyz>0 1 0</xyz>
      </axis>
    </joint>

    <joint name="rear_left_wheel_joint" type="revolute">
      <parent>base_link</parent>
      <child>rear_left_wheel</child>
      <axis>
        <xyz>0 1 0</xyz>
      </axis>
    </joint>

    <joint name="rear_right_wheel_joint" type="revolute">
      <parent>base_link</parent>
      <child>rear_right_wheel</child>
      <axis>
        <xyz>0 1 0</xyz>
      </axis>
    </joint>

    <!-- Differential Drive Plugin -->
    <plugin name="differential_drive_controller" filename="libgazebo_ros_diff_drive.so">
      <update_rate>30</update_rate>
      <left_joint>front_left_wheel_joint</left_joint>
      <right_joint>front_right_wheel_joint</right_joint>
      <wheel_separation>0.6</wheel_separation>
      <wheel_diameter>0.2</wheel_diameter>
      <max_wheel_torque>20</max_wheel_torque>
      <max_wheel_acceleration>1.0</max_wheel_acceleration>
      <command_topic>cmd_vel</command_topic>
      <publish_odom>true</publish_odom>
      <publish_odom_tf>true</publish_odom_tf>
      <publish_wheel_tf>true</publish_wheel_tf>
      <odometry_topic>odom</odometry_topic>
      <odometry_frame>odom</odometry_frame>
      <robot_base_frame>base_link</robot_base_frame>
    </plugin>

  </model>
</sdf>
